Workbook

Sheet Score sheet
A1: Plantilla oficial (m=10 corregido) rellenada con datos REALES de T1-T8 (PHMDC2019_Data). T1-T6: modelo SVR del notebook (Seccion 5, C=100, gamma=1.0), evaluacion en-muestra. T7-T8: pipeline completo del notebook (estimacion SVR + prediccion trans-fitting, Secciones 7.2/8.3).
A2: The grey columns should not be modified
A3: CORREGIDO: la formula original de penalizacion de monotonia usaba m=100. Los organizadores confirmaron que el valor correcto es m=10 (coincide con la Ec. 3 del paper). Ver data.phmsociety.org/2019datachallengesubmission/
A5: SPECIMEN LOAD CONDITIONS | D5: TRAINING SPECIMENS: CRACK GROWTH VS. NUMBER OF LOAD CYCLES
A6: Specimen NO. | B6: Loading Spectrum | D6: T1 | F6: T2 | H6: T3 | J6: T4 | L6: T5 | N6: T6 | P6: T7 | R6: T8
A7: T1 | B7: Constant | D7: Number of cycle | E7: Crack length (mm) [ESTIMADO/PREDICHO por el modelo del notebook] | F7: Number of cycle | G7: Crack length (mm) [ESTIMADO/PREDICHO por el modelo del notebook] | H7: Number of cycle | I7: Crack length (mm) [ESTIMADO/PREDICHO por el modelo del notebook] | J7: Number of cycle | K7: Crack length (mm) [ESTIMADO/PREDICHO por el modelo del notebook] | L7: Number of cycle | M7: Crack length (mm) [ESTIMADO/PREDICHO por el modelo del notebook] | N7: Number of cycle | O7: Crack length (mm) [ESTIMADO/PREDICHO por el modelo del notebook] | P7: Number of cycle | Q7: Crack length (mm) [ESTIMADO/PREDICHO por el modelo del notebook] | R7: Number of cycle | S7: Crack length (mm) [ESTIMADO/PREDICHO por el modelo del notebook]
A8: T2 | B8: Constant | D8: 50000 | E8: 1.12191 | F8: 50000 | G8: 1.12191 | H8: 14000 | I8: 2.538145 | J8: 55900 | K8: 1.12191 | L8: 46000 | M8: 1.12191 | N8: 55000 | O8: 1.12191 | P8: 36001 | Q8: 3.4188 | R8: 40000 | S8: 3.138776
A9: T3 | B9: Constant | D9: 60000 | E9: 3.35492 | F9: 70033 | G9: 3.149534 | H9: 50000 | I9: 1.12191 | J9: 60200 | K9: 1.710037 | L9: 51000 | M9: 1.147268 | N9: 60078 | O9: 0.719966 | P9: 40167 | Q9: 1.12191 | R9: 50000 | S9: 1.12191
A10: T4 | B10: Constant | D10: 62500 | E10: 3.657622 | F10: 72000 | G10: 3.515351 | H10: 57038 | I10: 4.118462 | J10: 65001 | K10: 2.270487 | L10: 56000 | M10: 3.739785 | N10: 68091 | O10: 0.234989 | P10: 44054 | Q10: 2.696113 | R10: 70000 | S10: 1.558118
A11: T5 | B11: Constant | D11: 65500 | E11: 3.388273 | H11: 60035 | I11: 4.041463 | J11: 67054 | K11: 1.574671 | N11: 69018 | O11: 2.787768 | P11: 47022 | Q11: 2.199418 | R11: 74883 | S11: 1.882384
A12: T6 | B12: Constant | D12: 69025 | E12: 4.610248 | H12: 62017 | I12: 3.925173 | J12: 70016 | K12: 3.22984 | N12: 72516 | O12: 4.7505 | P12: 49026 | Q12: 2.861338 | R12: 76931 | S12: 2.888621
A13: T7 | B13: Constant | D13: 70026 | E13: 4.335857 | H13: 64019 | I13: 2.917704 | J13: 71130 | K13: 4.159573 | N13: 73211 | O13: 5.005016 | P13: 51030 | Q13: 3.592704 | R13: 89237 | S13: 6.083083
A14: T8 | B14: Variable-amplitude | D14: 70766 | E14: 4.792734 | H14: 65029 | I14: 4.803361 | J14: 73210 | K14: 5.059971 | P14: 53019 | Q14: 4.715118 | R14: 92315 | S14: 7.739507
H15: 66012 | I15: 2.353731 | J15: 75045 | K15: 4.242833 | P15: 55031 | Q15: 7.03334 | R15: 96475 | S15: 11.660171
H16: 66510 | I16: 3.361902 | R16: 98492 | S16: 14.371807
R17: 100774 | S17: 18.575883
D19: PENALTY SCORE (m=10) | E19: ='Calculations sheet'!C63 | G19: ='Calculations sheet'!F63 | I19: ='Calculations sheet'!I63 | K19: ='Calculations sheet'!L63 | M19: ='Calculations sheet'!O63 | O19: ='Calculations sheet'!R63 | Q19: ='Calculations sheet'!U63 | S19: ='Calculations sheet'!X63

Sheet Calculations sheet
A1: NORMALIZED CRACK LENGTH
A2: T1 | D2: T2 | G2: T3 | J2: T4 | M2: T5 | P2: T6 | S2: T7 | V2: T8
A3: Number of cycle | B3: crack length (mm) | C3: normalized crack length (-) | D3: Number of cycle | E3: crack length (mm) | F3: normalized crack length (-) | G3: Number of cycle | H3: crack length (mm) | I3: normalized crack length (-) | J3: Number of cycle | K3: crack length (mm) | L3: normalized crack length (-) | M3: Number of cycle | N3: crack length (mm) | O3: normalized crack length (-) | P3: Number of cycle | Q3: crack length (mm) | R3: normalized crack length (-) | S3: Number of cycle | T3: crack length (mm) | U3: normalized crack length (-) | V3: Number of cycle | W3: crack length (mm) | X3: normalized crack length (-)
A4: 50000 | B4: 0 | C4: =B4/$B$10 | D4: 50000 | E4: 0 | F4: =E4/$E$6 | G4: 14000 | H4: 0 | I4: =H4/$H$12 | J4: 55900 | K4: 0 | L4: =K4/$K$11 | M4: 46000 | N4: 0 | O4: =N4/$N$6 | P4: 55000 | Q4: 0 | R4: =Q4/$Q$9 | S4: 36001 | T4: 0 | U4: =T4/$T$11 | V4: 40000 | W4: 0 | X4: =W4/$W$13
A5: 60000 | B5: 2.18 | C5: =B5/$B$10 | D5: 70033 | E5: 3.25 | F5: =E5/$E$6 | G5: 50000 | H5: 0 | I5: =H5/$H$12 | J5: 60200 | K5: 1.61 | L5: =K5/$K$11 | M5: 51000 | N5: 2.7 | O5: =N5/$N$6 | P5: 60078 | Q5: 0.82 | R5: =Q5/$Q$9 | S5: 40167 | T5: 0 | U5: =T5/$T$11 | V5: 50000 | W5: 0 | X5: =W5/$W$13
A6: 62500 | B6: 2.76 | C6: =B6/$B$10 | D6: 72000 | E6: 4.95 | F6: =E6/$E$6 | G6: 57038 | H6: 2.57 | I6: =H6/$H$12 | J6: 65001 | K6: 2.17 | L6: =K6/$K$11 | M6: 56000 | N6: 3.64 | O6: =N6/$N$6 | P6: 68091 | Q6: 2.36 | R6: =Q6/$Q$9 | S6: 44054 | T6: 2.07 | U6: =T6/$T$11 | V6: 70000 | W6: 0 | X6: =W6/$W$13
A7: 65500 | B7: 3.51 | C7: =B7/$B$10 | G7: 60035 | H7: 4.02 | I7: =H7/$H$12 | J7: 67054 | K7: 2.74 | L7: =K7/$K$11 | P7: 69018 | Q7: 3.36 | R7: =Q7/$Q$9 | S7: 47022 | T7: 3.14 | U7: =T7/$T$11 | V7: 74883 | W7: 1.94 | X7: =W7/$W$13
A8: 69025 | B8: 4.51 | C8: =B8/$B$10 | G8: 62017 | H8: 4.72 | I8: =H8/$H$12 | J8: 70016 | K8: 3.13 | L8: =K8/$K$11 | P8: 72516 | Q8: 4.65 | R8: =Q8/$Q$9 | S8: 49026 | T8: 3.56 | U8: =T8/$T$11 | V8: 76931 | W8: 2.5 | X8: =W8/$W$13
A9: 70026 | B9: 4.9 | C9: =B9/$B$10 | G9: 64019 | H9: 5.49 | I9: =H9/$H$12 | J9: 71130 | K9: 4.06 | L9: =K9/$K$11 | P9: 73211 | Q9: 5.08 | R9: =Q9/$Q$9 | S9: 51030 | T9: 4.13 | U9: =T9/$T$11 | V9: 89237 | W9: 3.71 | X9: =W9/$W$13
A10: 70766 | B10: 7.46 | C10: =B10/$B$10 | G10: 65029 | H10: 5.9 | I10: =H10/$H$12 | J10: 73210 | K10: 4.96 | L10: =K10/$K$11 | S10: 53019 | T10: 5.05 | U10: =T10/$T$11 | V10: 92315 | W10: 3.88 | X10: =W10/$W$13
G11: 66012 | H11: 6.52 | I11: =H11/$H$12 | J11: 75045 | K11: 7.24 | L11: =K11/$K$11 | S11: 55031 | T11: 7.22 | U11: =T11/$T$11 | V11: 96475 | W11: 4.61 | X11: =W11/$W$13
G12: 66510 | H12: 6.93 | I12: =H12/$H$12 | V12: 98492 | W12: 4.96 | X12: =W12/$W$13
V13: 100774 | W13: 5.52 | X13: =W13/$W$13
C16: =2+10*C4 | F16: =2+10*F4 | I16: =2+10*I4 | L16: =2+10*L4 | O16: =2+10*O4 | R16: =2+10*R4 | U16: =2+10*U4 | X16: =2+10*X4
C17: =2+10*C5 | F17: =2+10*F5 | I17: =2+10*I5 | L17: =2+10*L5 | O17: =2+10*O5 | R17: =2+10*R5 | U17: =2+10*U5 | X17: =2+10*X5
C18: =2+10*C6 | F18: =2+10*F6 | I18: =2+10*I6 | L18: =2+10*L6 | O18: =2+10*O6 | R18: =2+10*R6 | U18: =2+10*U6 | X18: =2+10*X6
C19: =2+10*C7 | I19: =2+10*I7 | L19: =2+10*L7 | R19: =2+10*R7 | U19: =2+10*U7 | X19: =2+10*X7
C20: =2+10*C8 | I20: =2+10*I8 | L20: =2+10*L8 | R20: =2+10*R8 | U20: =2+10*U8 | X20: =2+10*X8
C21: =2+10*C9 | I21: =2+10*I9 | L21: =2+10*L9 | R21: =2+10*R9 | U21: =2+10*U9 | X21: =2+10*X9
C22: =2+10*C10 | I22: =2+10*I10 | L22: =2+10*L10 | U22: =2+10*U10 | X22: =2+10*X10
I23: =2+10*I11 | L23: =2+10*L11 | U23: =2+10*U11 | X23: =2+10*X11
I24: =2+10*I12 | X24: =2+10*X12
X25: =2+10*X13
C28: =IF(('Score sheet'!E8/'Calculations sheet'!$B$10-'Calculations sheet'!C4)>=0, EXP(ABS('Score sheet'!E8/'Calculations sheet'!$B$10-'Calculations sheet'!C4)/0.5)-1, EXP(ABS('Score sheet'!E8/'Calculations sheet'!$B$10-'Calculations sheet'!C4)/0.2)-1) | F28: =IF(('Score sheet'!G8/'Calculations sheet'!$E$6-'Calculations sheet'!F4)>=0, EXP(ABS('Score sheet'!G8/'Calculations sheet'!$E$6-'Calculations sheet'!F4)/0.5)-1, EXP(ABS('Score sheet'!G8/'Calculations sheet'!$E$6-'Calculations sheet'!F4)/0.2)-1) | I28: =IF(('Score sheet'!I8/'Calculations sheet'!$H$12-'Calculations sheet'!I4)>=0, EXP(ABS('Score sheet'!I8/'Calculations sheet'!$H$12-'Calculations sheet'!I4)/0.5)-1, EXP(ABS('Score sheet'!I8/'Calculations sheet'!$H$12-'Calculations sheet'!I4)/0.2)-1) | L28: =IF(('Score sheet'!K8/'Calculations sheet'!$K$11-'Calculations sheet'!L4)>=0, EXP(ABS('Score sheet'!K8/'Calculations sheet'!$K$11-'Calculations sheet'!L4)/0.5)-1, EXP(ABS('Score sheet'!K8/'Calculations sheet'!$K$11-'Calculations sheet'!L4)/0.2)-1) | O28: =IF(('Score sheet'!M8/'Calculations sheet'!$N$6-'Calculations sheet'!O4)>=0, EXP(ABS('Score sheet'!M8/'Calculations sheet'!$N$6-'Calculations sheet'!O4)/0.5)-1, EXP(ABS('Score sheet'!M8/'Calculations sheet'!$N$6-'Calculations sheet'!O4)/0.2)-1) | R28: =IF(('Score sheet'!O8/'Calculations sheet'!$Q$9-'Calculations sheet'!R4)>=0, EXP(ABS('Score sheet'!O8/'Calculations sheet'!$Q$9-'Calculations sheet'!R4)/0.5)-1, EXP(ABS('Score sheet'!O8/'Calculations sheet'!$Q$9-'Calculations sheet'!R4)/0.2)-1) | U28: =IF(('Score sheet'!Q8/'Calculations sheet'!$T$11-'Calculations sheet'!U4)>=0, EXP(ABS('Score sheet'!Q8/'Calculations sheet'!$T$11-'Calculations sheet'!U4)/0.5)-1, EXP(ABS('Score sheet'!Q8/'Calculations sheet'!$T$11-'Calculations sheet'!U4)/0.2)-1) | X28: =IF(('Score sheet'!S8/'Calculations sheet'!$W$13-'Calculations sheet'!X4)>=0, EXP(ABS('Score sheet'!S8/'Calculations sheet'!$W$13-'Calculations sheet'!X4)/0.5)-1, EXP(ABS('Score sheet'!S8/'Calculations sheet'!$W$13-'Calculations sheet'!X4)/0.2)-1)
C29: =IF(('Score sheet'!E9/'Calculations sheet'!$B$10-'Calculations sheet'!C5)>=0, EXP(ABS('Score sheet'!E9/'Calculations sheet'!$B$10-'Calculations sheet'!C5)/0.5)-1, EXP(ABS('Score sheet'!E9/'Calculations sheet'!$B$10-'Calculations sheet'!C5)/0.2)-1) | F29: =IF(('Score sheet'!G9/'Calculations sheet'!$E$6-'Calculations sheet'!F5)>=0, EXP(ABS('Score sheet'!G9/'Calculations sheet'!$E$6-'Calculations sheet'!F5)/0.5)-1, EXP(ABS('Score sheet'!G9/'Calculations sheet'!$E$6-'Calculations sheet'!F5)/0.2)-1) | I29: =IF(('Score sheet'!I9/'Calculations sheet'!$H$12-'Calculations sheet'!I5)>=0, EXP(ABS('Score sheet'!I9/'Calculations sheet'!$H$12-'Calculations sheet'!I5)/0.5)-1, EXP(ABS('Score sheet'!I9/'Calculations sheet'!$H$12-'Calculations sheet'!I5)/0.2)-1) | L29: =IF(('Score sheet'!K9/'Calculations sheet'!$K$11-'Calculations sheet'!L5)>=0, EXP(ABS('Score sheet'!K9/'Calculations sheet'!$K$11-'Calculations sheet'!L5)/0.5)-1, EXP(ABS('Score sheet'!K9/'Calculations sheet'!$K$11-'Calculations sheet'!L5)/0.2)-1) | O29: =IF(('Score sheet'!M9/'Calculations sheet'!$N$6-'Calculations sheet'!O5)>=0, EXP(ABS('Score sheet'!M9/'Calculations sheet'!$N$6-'Calculations sheet'!O5)/0.5)-1, EXP(ABS('Score sheet'!M9/'Calculations sheet'!$N$6-'Calculations sheet'!O5)/0.2)-1) | R29: =IF(('Score sheet'!O9/'Calculations sheet'!$Q$9-'Calculations sheet'!R5)>=0, EXP(ABS('Score sheet'!O9/'Calculations sheet'!$Q$9-'Calculations sheet'!R5)/0.5)-1, EXP(ABS('Score sheet'!O9/'Calculations sheet'!$Q$9-'Calculations sheet'!R5)/0.2)-1) | U29: =IF(('Score sheet'!Q9/'Calculations sheet'!$T$11-'Calculations sheet'!U5)>=0, EXP(ABS('Score sheet'!Q9/'Calculations sheet'!$T$11-'Calculations sheet'!U5)/0.5)-1, EXP(ABS('Score sheet'!Q9/'Calculations sheet'!$T$11-'Calculations sheet'!U5)/0.2)-1) | X29: =IF(('Score sheet'!S9/'Calculations sheet'!$W$13-'Calculations sheet'!X5)>=0, EXP(ABS('Score sheet'!S9/'Calculations sheet'!$W$13-'Calculations sheet'!X5)/0.5)-1, EXP(ABS('Score sheet'!S9/'Calculations sheet'!$W$13-'Calculations sheet'!X5)/0.2)-1)
C30: =IF(('Score sheet'!E10/'Calculations sheet'!$B$10-'Calculations sheet'!C6)>=0, EXP(ABS('Score sheet'!E10/'Calculations sheet'!$B$10-'Calculations sheet'!C6)/0.5)-1, EXP(ABS('Score sheet'!E10/'Calculations sheet'!$B$10-'Calculations sheet'!C6)/0.2)-1) | F30: =IF(('Score sheet'!G10/'Calculations sheet'!$E$6-'Calculations sheet'!F6)>=0, EXP(ABS('Score sheet'!G10/'Calculations sheet'!$E$6-'Calculations sheet'!F6)/0.5)-1, EXP(ABS('Score sheet'!G10/'Calculations sheet'!$E$6-'Calculations sheet'!F6)/0.2)-1) | I30: =IF(('Score sheet'!I10/'Calculations sheet'!$H$12-'Calculations sheet'!I6)>=0, EXP(ABS('Score sheet'!I10/'Calculations sheet'!$H$12-'Calculations sheet'!I6)/0.5)-1, EXP(ABS('Score sheet'!I10/'Calculations sheet'!$H$12-'Calculations sheet'!I6)/0.2)-1) | L30: =IF(('Score sheet'!K10/'Calculations sheet'!$K$11-'Calculations sheet'!L6)>=0, EXP(ABS('Score sheet'!K10/'Calculations sheet'!$K$11-'Calculations sheet'!L6)/0.5)-1, EXP(ABS('Score sheet'!K10/'Calculations sheet'!$K$11-'Calculations sheet'!L6)/0.2)-1) | O30: =IF(('Score sheet'!M10/'Calculations sheet'!$N$6-'Calculations sheet'!O6)>=0, EXP(ABS('Score sheet'!M10/'Calculations sheet'!$N$6-'Calculations sheet'!O6)/0.5)-1, EXP(ABS('Score sheet'!M10/'Calculations sheet'!$N$6-'Calculations sheet'!O6)/0.2)-1) | R30: =IF(('Score sheet'!O10/'Calculations sheet'!$Q$9-'Calculations sheet'!R6)>=0, EXP(ABS('Score sheet'!O10/'Calculations sheet'!$Q$9-'Calculations sheet'!R6)/0.5)-1, EXP(ABS('Score sheet'!O10/'Calculations sheet'!$Q$9-'Calculations sheet'!R6)/0.2)-1) | U30: =IF(('Score sheet'!Q10/'Calculations sheet'!$T$11-'Calculations sheet'!U6)>=0, EXP(ABS('Score sheet'!Q10/'Calculations sheet'!$T$11-'Calculations sheet'!U6)/0.5)-1, EXP(ABS('Score sheet'!Q10/'Calculations sheet'!$T$11-'Calculations sheet'!U6)/0.2)-1) | X30: =IF(('Score sheet'!S10/'Calculations sheet'!$W$13-'Calculations sheet'!X6)>=0, EXP(ABS('Score sheet'!S10/'Calculations sheet'!$W$13-'Calculations sheet'!X6)/0.5)-1, EXP(ABS('Score sheet'!S10/'Calculations sheet'!$W$13-'Calculations sheet'!X6)/0.2)-1)
C31: =IF(('Score sheet'!E11/'Calculations sheet'!$B$10-'Calculations sheet'!C7)>=0, EXP(ABS('Score sheet'!E11/'Calculations sheet'!$B$10-'Calculations sheet'!C7)/0.5)-1, EXP(ABS('Score sheet'!E11/'Calculations sheet'!$B$10-'Calculations sheet'!C7)/0.2)-1) | I31: =IF(('Score sheet'!I11/'Calculations sheet'!$H$12-'Calculations sheet'!I7)>=0, EXP(ABS('Score sheet'!I11/'Calculations sheet'!$H$12-'Calculations sheet'!I7)/0.5)-1, EXP(ABS('Score sheet'!I11/'Calculations sheet'!$H$12-'Calculations sheet'!I7)/0.2)-1) | L31: =IF(('Score sheet'!K11/'Calculations sheet'!$K$11-'Calculations sheet'!L7)>=0, EXP(ABS('Score sheet'!K11/'Calculations sheet'!$K$11-'Calculations sheet'!L7)/0.5)-1, EXP(ABS('Score sheet'!K11/'Calculations sheet'!$K$11-'Calculations sheet'!L7)/0.2)-1) | R31: =IF(('Score sheet'!O11/'Calculations sheet'!$Q$9-'Calculations sheet'!R7)>=0, EXP(ABS('Score sheet'!O11/'Calculations sheet'!$Q$9-'Calculations sheet'!R7)/0.5)-1, EXP(ABS('Score sheet'!O11/'Calculations sheet'!$Q$9-'Calculations sheet'!R7)/0.2)-1) | U31: =IF(('Score sheet'!Q11/'Calculations sheet'!$T$11-'Calculations sheet'!U7)>=0, EXP(ABS('Score sheet'!Q11/'Calculations sheet'!$T$11-'Calculations sheet'!U7)/0.5)-1, EXP(ABS('Score sheet'!Q11/'Calculations sheet'!$T$11-'Calculations sheet'!U7)/0.2)-1) | X31: =IF(('Score sheet'!S11/'Calculations sheet'!$W$13-'Calculations sheet'!X7)>=0, EXP(ABS('Score sheet'!S11/'Calculations sheet'!$W$13-'Calculations sheet'!X7)/0.5)-1, EXP(ABS('Score sheet'!S11/'Calculations sheet'!$W$13-'Calculations sheet'!X7)/0.2)-1)
C32: =IF(('Score sheet'!E12/'Calculations sheet'!$B$10-'Calculations sheet'!C8)>=0, EXP(ABS('Score sheet'!E12/'Calculations sheet'!$B$10-'Calculations sheet'!C8)/0.5)-1, EXP(ABS('Score sheet'!E12/'Calculations sheet'!$B$10-'Calculations sheet'!C8)/0.2)-1) | I32: =IF(('Score sheet'!I12/'Calculations sheet'!$H$12-'Calculations sheet'!I8)>=0, EXP(ABS('Score sheet'!I12/'Calculations sheet'!$H$12-'Calculations sheet'!I8)/0.5)-1, EXP(ABS('Score sheet'!I12/'Calculations sheet'!$H$12-'Calculations sheet'!I8)/0.2)-1) | L32: =IF(('Score sheet'!K12/'Calculations sheet'!$K$11-'Calculations sheet'!L8)>=0, EXP(ABS('Score sheet'!K12/'Calculations sheet'!$K$11-'Calculations sheet'!L8)/0.5)-1, EXP(ABS('Score sheet'!K12/'Calculations sheet'!$K$11-'Calculations sheet'!L8)/0.2)-1) | R32: =IF(('Score sheet'!O12/'Calculations sheet'!$Q$9-'Calculations sheet'!R8)>=0, EXP(ABS('Score sheet'!O12/'Calculations sheet'!$Q$9-'Calculations sheet'!R8)/0.5)-1, EXP(ABS('Score sheet'!O12/'Calculations sheet'!$Q$9-'Calculations sheet'!R8)/0.2)-1) | U32: =IF(('Score sheet'!Q12/'Calculations sheet'!$T$11-'Calculations sheet'!U8)>=0, EXP(ABS('Score sheet'!Q12/'Calculations sheet'!$T$11-'Calculations sheet'!U8)/0.5)-1, EXP(ABS('Score sheet'!Q12/'Calculations sheet'!$T$11-'Calculations sheet'!U8)/0.2)-1) | X32: =IF(('Score sheet'!S12/'Calculations sheet'!$W$13-'Calculations sheet'!X8)>=0, EXP(ABS('Score sheet'!S12/'Calculations sheet'!$W$13-'Calculations sheet'!X8)/0.5)-1, EXP(ABS('Score sheet'!S12/'Calculations sheet'!$W$13-'Calculations sheet'!X8)/0.2)-1)
C33: =IF(('Score sheet'!E13/'Calculations sheet'!$B$10-'Calculations sheet'!C9)>=0, EXP(ABS('Score sheet'!E13/'Calculations sheet'!$B$10-'Calculations sheet'!C9)/0.5)-1, EXP(ABS('Score sheet'!E13/'Calculations sheet'!$B$10-'Calculations sheet'!C9)/0.2)-1) | I33: =IF(('Score sheet'!I13/'Calculations sheet'!$H$12-'Calculations sheet'!I9)>=0, EXP(ABS('Score sheet'!I13/'Calculations sheet'!$H$12-'Calculations sheet'!I9)/0.5)-1, EXP(ABS('Score sheet'!I13/'Calculations sheet'!$H$12-'Calculations sheet'!I9)/0.2)-1) | L33: =IF(('Score sheet'!K13/'Calculations sheet'!$K$11-'Calculations sheet'!L9)>=0, EXP(ABS('Score sheet'!K13/'Calculations sheet'!$K$11-'Calculations sheet'!L9)/0.5)-1, EXP(ABS('Score sheet'!K13/'Calculations sheet'!$K$11-'Calculations sheet'!L9)/0.2)-1) | R33: =IF(('Score sheet'!O13/'Calculations sheet'!$Q$9-'Calculations sheet'!R9)>=0, EXP(ABS('Score sheet'!O13/'Calculations sheet'!$Q$9-'Calculations sheet'!R9)/0.5)-1, EXP(ABS('Score sheet'!O13/'Calculations sheet'!$Q$9-'Calculations sheet'!R9)/0.2)-1) | U33: =IF(('Score sheet'!Q13/'Calculations sheet'!$T$11-'Calculations sheet'!U9)>=0, EXP(ABS('Score sheet'!Q13/'Calculations sheet'!$T$11-'Calculations sheet'!U9)/0.5)-1, EXP(ABS('Score sheet'!Q13/'Calculations sheet'!$T$11-'Calculations sheet'!U9)/0.2)-1) | X33: =IF(('Score sheet'!S13/'Calculations sheet'!$W$13-'Calculations sheet'!X9)>=0, EXP(ABS('Score sheet'!S13/'Calculations sheet'!$W$13-'Calculations sheet'!X9)/0.5)-1, EXP(ABS('Score sheet'!S13/'Calculations sheet'!$W$13-'Calculations sheet'!X9)/0.2)-1)
C34: =IF(('Score sheet'!E14/'Calculations sheet'!$B$10-'Calculations sheet'!C10)>=0, EXP(ABS('Score sheet'!E14/'Calculations sheet'!$B$10-'Calculations sheet'!C10)/0.5)-1, EXP(ABS('Score sheet'!E14/'Calculations sheet'!$B$10-'Calculations sheet'!C10)/0.2)-1) | I34: =IF(('Score sheet'!I14/'Calculations sheet'!$H$12-'Calculations sheet'!I10)>=0, EXP(ABS('Score sheet'!I14/'Calculations sheet'!$H$12-'Calculations sheet'!I10)/0.5)-1, EXP(ABS('Score sheet'!I14/'Calculations sheet'!$H$12-'Calculations sheet'!I10)/0.2)-1) | L34: =IF(('Score sheet'!K14/'Calculations sheet'!$K$11-'Calculations sheet'!L10)>=0, EXP(ABS('Score sheet'!K14/'Calculations sheet'!$K$11-'Calculations sheet'!L10)/0.5)-1, EXP(ABS('Score sheet'!K14/'Calculations sheet'!$K$11-'Calculations sheet'!L10)/0.2)-1) | U34: =IF(('Score sheet'!Q14/'Calculations sheet'!$T$11-'Calculations sheet'!U10)>=0, EXP(ABS('Score sheet'!Q14/'Calculations sheet'!$T$11-'Calculations sheet'!U10)/0.5)-1, EXP(ABS('Score sheet'!Q14/'Calculations sheet'!$T$11-'Calculations sheet'!U10)/0.2)-1) | X34: =IF(('Score sheet'!S14/'Calculations sheet'!$W$13-'Calculations sheet'!X10)>=0, EXP(ABS('Score sheet'!S14/'Calculations sheet'!$W$13-'Calculations sheet'!X10)/0.5)-1, EXP(ABS('Score sheet'!S14/'Calculations sheet'!$W$13-'Calculations sheet'!X10)/0.2)-1)
I35: =IF(('Score sheet'!I15/'Calculations sheet'!$H$12-'Calculations sheet'!I11)>=0, EXP(ABS('Score sheet'!I15/'Calculations sheet'!$H$12-'Calculations sheet'!I11)/0.5)-1, EXP(ABS('Score sheet'!I15/'Calculations sheet'!$H$12-'Calculations sheet'!I11)/0.2)-1) | L35: =IF(('Score sheet'!K15/'Calculations sheet'!$K$11-'Calculations sheet'!L11)>=0, EXP(ABS('Score sheet'!K15/'Calculations sheet'!$K$11-'Calculations sheet'!L11)/0.5)-1, EXP(ABS('Score sheet'!K15/'Calculations sheet'!$K$11-'Calculations sheet'!L11)/0.2)-1) | U35: =IF(('Score sheet'!Q15/'Calculations sheet'!$T$11-'Calculations sheet'!U11)>=0, EXP(ABS('Score sheet'!Q15/'Calculations sheet'!$T$11-'Calculations sheet'!U11)/0.5)-1, EXP(ABS('Score sheet'!Q15/'Calculations sheet'!$T$11-'Calculations sheet'!U11)/0.2)-1) | X35: =IF(('Score sheet'!S15/'Calculations sheet'!$W$13-'Calculations sheet'!X11)>=0, EXP(ABS('Score sheet'!S15/'Calculations sheet'!$W$13-'Calculations sheet'!X11)/0.5)-1, EXP(ABS('Score sheet'!S15/'Calculations sheet'!$W$13-'Calculations sheet'!X11)/0.2)-1)
I36: =IF(('Score sheet'!I16/'Calculations sheet'!$H$12-'Calculations sheet'!I12)>=0, EXP(ABS('Score sheet'!I16/'Calculations sheet'!$H$12-'Calculations sheet'!I12)/0.5)-1, EXP(ABS('Score sheet'!I16/'Calculations sheet'!$H$12-'Calculations sheet'!I12)/0.2)-1) | X36: =IF(('Score sheet'!S16/'Calculations sheet'!$W$13-'Calculations sheet'!X12)>=0, EXP(ABS('Score sheet'!S16/'Calculations sheet'!$W$13-'Calculations sheet'!X12)/0.5)-1, EXP(ABS('Score sheet'!S16/'Calculations sheet'!$W$13-'Calculations sheet'!X12)/0.2)-1)
X37: =IF(('Score sheet'!S17/'Calculations sheet'!$W$13-'Calculations sheet'!X13)>=0, EXP(ABS('Score sheet'!S17/'Calculations sheet'!$W$13-'Calculations sheet'!X13)/0.5)-1, EXP(ABS('Score sheet'!S17/'Calculations sheet'!$W$13-'Calculations sheet'!X13)/0.2)-1)
C40: 1 | F40: 1 | I40: 1 | L40: 1 | O40: 1 | R40: 1 | U40: 1 | X40: 1
C41: =IF(('Score sheet'!E9/'Calculations sheet'!$B$10-'Score sheet'!E8/'Calculations sheet'!$B$10)<0, 1+10*ABS('Score sheet'!E9/'Calculations sheet'!$B$10-'Score sheet'!E8/'Calculations sheet'!$B$10), 1) | F41: =IF(('Score sheet'!G9/'Calculations sheet'!$E$6-'Score sheet'!G8/'Calculations sheet'!$E$6)<0, 1+10*ABS('Score sheet'!G9/'Calculations sheet'!$E$6-'Score sheet'!G8/'Calculations sheet'!$E$6), 1) | I41: =IF(('Score sheet'!I9/'Calculations sheet'!$H$12-'Score sheet'!I8/'Calculations sheet'!$H$12)<0, 1+10*ABS('Score sheet'!I9/'Calculations sheet'!$H$12-'Score sheet'!I8/'Calculations sheet'!$H$12), 1) | L41: =IF(('Score sheet'!K9/'Calculations sheet'!$K$11-'Score sheet'!K8/'Calculations sheet'!$K$11)<0, 1+10*ABS('Score sheet'!K9/'Calculations sheet'!$K$11-'Score sheet'!K8/'Calculations sheet'!$K$11), 1) | O41: =IF(('Score sheet'!M9/'Calculations sheet'!$N$6-'Score sheet'!M8/'Calculations sheet'!$N$6)<0, 1+10*ABS('Score sheet'!M9/'Calculations sheet'!$N$6-'Score sheet'!M8/'Calculations sheet'!$N$6), 1) | R41: =IF(('Score sheet'!O9/'Calculations sheet'!$Q$9-'Score sheet'!O8/'Calculations sheet'!$Q$9)<0, 1+10*ABS('Score sheet'!O9/'Calculations sheet'!$Q$9-'Score sheet'!O8/'Calculations sheet'!$Q$9), 1) | U41: =IF(('Score sheet'!Q9/'Calculations sheet'!$T$11-'Score sheet'!Q8/'Calculations sheet'!$T$11)<0, 1+10*ABS('Score sheet'!Q9/'Calculations sheet'!$T$11-'Score sheet'!Q8/'Calculations sheet'!$T$11), 1) | X41: =IF(('Score sheet'!S9/'Calculations sheet'!$W$13-'Score sheet'!S8/'Calculations sheet'!$W$13)<0, 1+10*ABS('Score sheet'!S9/'Calculations sheet'!$W$13-'Score sheet'!S8/'Calculations sheet'!$W$13), 1)
C42: =IF(('Score sheet'!E10/'Calculations sheet'!$B$10-'Score sheet'!E9/'Calculations sheet'!$B$10)<0, 1+10*ABS('Score sheet'!E10/'Calculations sheet'!$B$10-'Score sheet'!E9/'Calculations sheet'!$B$10), 1) | F42: =IF(('Score sheet'!G10/'Calculations sheet'!$E$6-'Score sheet'!G9/'Calculations sheet'!$E$6)<0, 1+10*ABS('Score sheet'!G10/'Calculations sheet'!$E$6-'Score sheet'!G9/'Calculations sheet'!$E$6), 1) | I42: =IF(('Score sheet'!I10/'Calculations sheet'!$H$12-'Score sheet'!I9/'Calculations sheet'!$H$12)<0, 1+10*ABS('Score sheet'!I10/'Calculations sheet'!$H$12-'Score sheet'!I9/'Calculations sheet'!$H$12), 1) | L42: =IF(('Score sheet'!K10/'Calculations sheet'!$K$11-'Score sheet'!K9/'Calculations sheet'!$K$11)<0, 1+10*ABS('Score sheet'!K10/'Calculations sheet'!$K$11-'Score sheet'!K9/'Calculations sheet'!$K$11), 1) | O42: =IF(('Score sheet'!M10/'Calculations sheet'!$N$6-'Score sheet'!M9/'Calculations sheet'!$N$6)<0, 1+10*ABS('Score sheet'!M10/'Calculations sheet'!$N$6-'Score sheet'!M9/'Calculations sheet'!$N$6), 1) | R42: =IF(('Score sheet'!O10/'Calculations sheet'!$Q$9-'Score sheet'!O9/'Calculations sheet'!$Q$9)<0, 1+10*ABS('Score sheet'!O10/'Calculations sheet'!$Q$9-'Score sheet'!O9/'Calculations sheet'!$Q$9), 1) | U42: =IF(('Score sheet'!Q10/'Calculations sheet'!$T$11-'Score sheet'!Q9/'Calculations sheet'!$T$11)<0, 1+10*ABS('Score sheet'!Q10/'Calculations sheet'!$T$11-'Score sheet'!Q9/'Calculations sheet'!$T$11), 1) | X42: =IF(('Score sheet'!S10/'Calculations sheet'!$W$13-'Score sheet'!S9/'Calculations sheet'!$W$13)<0, 1+10*ABS('Score sheet'!S10/'Calculations sheet'!$W$13-'Score sheet'!S9/'Calculations sheet'!$W$13), 1)
C43: =IF(('Score sheet'!E11/'Calculations sheet'!$B$10-'Score sheet'!E10/'Calculations sheet'!$B$10)<0, 1+10*ABS('Score sheet'!E11/'Calculations sheet'!$B$10-'Score sheet'!E10/'Calculations sheet'!$B$10), 1) | I43: =IF(('Score sheet'!I11/'Calculations sheet'!$H$12-'Score sheet'!I10/'Calculations sheet'!$H$12)<0, 1+10*ABS('Score sheet'!I11/'Calculations sheet'!$H$12-'Score sheet'!I10/'Calculations sheet'!$H$12), 1) | L43: =IF(('Score sheet'!K11/'Calculations sheet'!$K$11-'Score sheet'!K10/'Calculations sheet'!$K$11)<0, 1+10*ABS('Score sheet'!K11/'Calculations sheet'!$K$11-'Score sheet'!K10/'Calculations sheet'!$K$11), 1) | R43: =IF(('Score sheet'!O11/'Calculations sheet'!$Q$9-'Score sheet'!O10/'Calculations sheet'!$Q$9)<0, 1+10*ABS('Score sheet'!O11/'Calculations sheet'!$Q$9-'Score sheet'!O10/'Calculations sheet'!$Q$9), 1) | U43: =IF(('Score sheet'!Q11/'Calculations sheet'!$T$11-'Score sheet'!Q10/'Calculations sheet'!$T$11)<0, 1+10*ABS('Score sheet'!Q11/'Calculations sheet'!$T$11-'Score sheet'!Q10/'Calculations sheet'!$T$11), 1) | X43: =IF(('Score sheet'!S11/'Calculations sheet'!$W$13-'Score sheet'!S10/'Calculations sheet'!$W$13)<0, 1+10*ABS('Score sheet'!S11/'Calculations sheet'!$W$13-'Score sheet'!S10/'Calculations sheet'!$W$13), 1)
C44: =IF(('Score sheet'!E12/'Calculations sheet'!$B$10-'Score sheet'!E11/'Calculations sheet'!$B$10)<0, 1+10*ABS('Score sheet'!E12/'Calculations sheet'!$B$10-'Score sheet'!E11/'Calculations sheet'!$B$10), 1) | I44: =IF(('Score sheet'!I12/'Calculations sheet'!$H$12-'Score sheet'!I11/'Calculations sheet'!$H$12)<0, 1+10*ABS('Score sheet'!I12/'Calculations sheet'!$H$12-'Score sheet'!I11/'Calculations sheet'!$H$12), 1) | L44: =IF(('Score sheet'!K12/'Calculations sheet'!$K$11-'Score sheet'!K11/'Calculations sheet'!$K$11)<0, 1+10*ABS('Score sheet'!K12/'Calculations sheet'!$K$11-'Score sheet'!K11/'Calculations sheet'!$K$11), 1) | R44: =IF(('Score sheet'!O12/'Calculations sheet'!$Q$9-'Score sheet'!O11/'Calculations sheet'!$Q$9)<0, 1+10*ABS('Score sheet'!O12/'Calculations sheet'!$Q$9-'Score sheet'!O11/'Calculations sheet'!$Q$9), 1) | U44: =IF(('Score sheet'!Q12/'Calculations sheet'!$T$11-'Score sheet'!Q11/'Calculations sheet'!$T$11)<0, 1+10*ABS('Score sheet'!Q12/'Calculations sheet'!$T$11-'Score sheet'!Q11/'Calculations sheet'!$T$11), 1) | X44: =IF(('Score sheet'!S12/'Calculations sheet'!$W$13-'Score sheet'!S11/'Calculations sheet'!$W$13)<0, 1+10*ABS('Score sheet'!S12/'Calculations sheet'!$W$13-'Score sheet'!S11/'Calculations sheet'!$W$13), 1)
C45: =IF(('Score sheet'!E13/'Calculations sheet'!$B$10-'Score sheet'!E12/'Calculations sheet'!$B$10)<0, 1+10*ABS('Score sheet'!E13/'Calculations sheet'!$B$10-'Score sheet'!E12/'Calculations sheet'!$B$10), 1) | I45: =IF(('Score sheet'!I13/'Calculations sheet'!$H$12-'Score sheet'!I12/'Calculations sheet'!$H$12)<0, 1+10*ABS('Score sheet'!I13/'Calculations sheet'!$H$12-'Score sheet'!I12/'Calculations sheet'!$H$12), 1) | L45: =IF(('Score sheet'!K13/'Calculations sheet'!$K$11-'Score sheet'!K12/'Calculations sheet'!$K$11)<0, 1+10*ABS('Score sheet'!K13/'Calculations sheet'!$K$11-'Score sheet'!K12/'Calculations sheet'!$K$11), 1) | R45: =IF(('Score sheet'!O13/'Calculations sheet'!$Q$9-'Score sheet'!O12/'Calculations sheet'!$Q$9)<0, 1+10*ABS('Score sheet'!O13/'Calculations sheet'!$Q$9-'Score sheet'!O12/'Calculations sheet'!$Q$9), 1) | U45: =IF(('Score sheet'!Q13/'Calculations sheet'!$T$11-'Score sheet'!Q12/'Calculations sheet'!$T$11)<0, 1+10*ABS('Score sheet'!Q13/'Calculations sheet'!$T$11-'Score sheet'!Q12/'Calculations sheet'!$T$11), 1) | X45: =IF(('Score sheet'!S13/'Calculations sheet'!$W$13-'Score sheet'!S12/'Calculations sheet'!$W$13)<0, 1+10*ABS('Score sheet'!S13/'Calculations sheet'!$W$13-'Score sheet'!S12/'Calculations sheet'!$W$13), 1)
C46: =IF(('Score sheet'!E14/'Calculations sheet'!$B$10-'Score sheet'!E13/'Calculations sheet'!$B$10)<0, 1+10*ABS('Score sheet'!E14/'Calculations sheet'!$B$10-'Score sheet'!E13/'Calculations sheet'!$B$10), 1) | I46: =IF(('Score sheet'!I14/'Calculations sheet'!$H$12-'Score sheet'!I13/'Calculations sheet'!$H$12)<0, 1+10*ABS('Score sheet'!I14/'Calculations sheet'!$H$12-'Score sheet'!I13/'Calculations sheet'!$H$12), 1) | L46: =IF(('Score sheet'!K14/'Calculations sheet'!$K$11-'Score sheet'!K13/'Calculations sheet'!$K$11)<0, 1+10*ABS('Score sheet'!K14/'Calculations sheet'!$K$11-'Score sheet'!K13/'Calculations sheet'!$K$11), 1) | U46: =IF(('Score sheet'!Q14/'Calculations sheet'!$T$11-'Score sheet'!Q13/'Calculations sheet'!$T$11)<0, 1+10*ABS('Score sheet'!Q14/'Calculations sheet'!$T$11-'Score sheet'!Q13/'Calculations sheet'!$T$11), 1) | X46: =IF(('Score sheet'!S14/'Calculations sheet'!$W$13-'Score sheet'!S13/'Calculations sheet'!$W$13)<0, 1+10*ABS('Score sheet'!S14/'Calculations sheet'!$W$13-'Score sheet'!S13/'Calculations sheet'!$W$13), 1)
...
